<mujoco model="printer">
  <compiler angle="radian" meshdir="/home/yuquan/local/mc_rtc_related/mc_int_obj_description/meshes/printer/"/>
<default>
  <default class="collision">
    <geom condim="3" group="0" />
  </default>
</default>

  <asset>
    <mesh name="printer" file="printer.stl"/>
    <mesh name="rack" file="rack.stl"/>
  </asset>

  <worldbody>
<geom class="collision" mesh="printer"/>
<body name="printer_base_link"/>
    <geom type="mesh" contype="0" conaffinity="0" group="1" density="0" rgba="1 1 1 1" mesh="printer"/>
    <body name="rack" pos="0.078 0 -0.11">
      <inertial pos="0 0 0" mass="1" diaginertia="1 1 1"/>
      <joint name="rack" pos="0 0 0" axis="1 0 0" type="slide" range="-0.02 0.2"/>
      <geom type="mesh" contype="0" conaffinity="0" group="1" density="0" rgba="0.8 0.8 0.8 1" mesh="rack"/>
    </body>
  </worldbody>
</mujoco>
