<mujoco model="valve_handle">
  <compiler angle="radian" meshdir="/home/yuquan/local/mc_rtc_related/mc_int_obj_description/meshes/valve_handle/"/>
<default>
  <default class="collision">
    <geom condim="3" group="0" />
  </default>
</default>

  <asset>
    <mesh name="valve" file="valve.stl"/>
    <mesh name="handle" file="handle.stl"/>
  </asset>

  <worldbody>
<geom class="collision" mesh="valve_handle"/>
<body name="valve_handle_base_link"/>
    <body name="valve">
      <inertial pos="0 0 0" mass="1" diaginertia="1 1 1"/>
      <joint name="valve" pos="0 0 0" axis="1 0 0"/>
      <geom type="mesh" contype="0" conaffinity="0" group="1" density="0" rgba="1 0 0 1" mesh="valve"/>
      <body name="handle" pos="0.09399 0 0.202497" quat="0.707107 0 0.707107 0">
        <inertial pos="0 0 0" mass="0.1" diaginertia="1 1 1"/>
        <joint name="handle" pos="0 0 0" axis="0 0 1"/>
        <geom type="mesh" contype="0" conaffinity="0" group="1" density="0" rgba="1 0 0 1" mesh="handle"/>
      </body>
    </body>
  </worldbody>
</mujoco>
